Traceback (most recent call last):
  File "data_preprocessing.py", line 146, in <module>
    df = data_preparation(categories, period_start, period_end)
  File "data_preprocessing.py", line 138, in data_preparation
    cluster_complete = fill_dataframe(category, tensors, cluster)
  File "data_preprocessing.py", line 93, in fill_dataframe
    cluster["forward_citations"] = cluster["forward_citations"].apply(categorise_output, axis=1)
  File "/cluster/raid/home/michael.tsesmelis/SideProject/lib/python3.8/site-packages/pandas/core/series.py", line 4357, in apply
    return SeriesApply(self, func, convert_dtype, args, kwargs).apply()
  File "/cluster/raid/home/michael.tsesmelis/SideProject/lib/python3.8/site-packages/pandas/core/apply.py", line 1043, in apply
    return self.apply_standard()
  File "/cluster/raid/home/michael.tsesmelis/SideProject/lib/python3.8/site-packages/pandas/core/apply.py", line 1098, in apply_standard
    mapped = lib.map_infer(
  File "pandas/_libs/lib.pyx", line 2859, in pandas._libs.lib.map_infer
  File "/cluster/raid/home/michael.tsesmelis/SideProject/lib/python3.8/site-packages/pandas/core/apply.py", line 131, in f
    return func(x, *args, **kwargs)
TypeError: categorise_output() got an unexpected keyword argument 'axis'
